Workbook

Sheet 2023 Yield
N1: Tomatoes | Y1: Potatoes | AF1: Day Total
A2: Date | B2: Raspberries | C2: Strawberries | D2: Snap Peas | E2: Green Beans | F2: Green Bean Seeds | G2: Onions (qty) | H2: Broccoli | I2: Blueberries | J2: Cucumber | K2: Green Pepper | L2: Plum | M2: Black Berries | N2: Small | O2: Golden Cherry | P2: Large | Q2: Heirloom | R2: Golden Jubilee | S2: San Marzano | T2: Peaches | U2: Corn | V2: Corn Seeds | W2: Banana Pepper | X2: Acorn Squash | Y2: Red | Z2: Yellow/Yukon | AA2: Butternut Squash | AB2: Jalapeno | AC2: Zucchini | AD2: Pumpkin | AE2: Brussel Sprouts | AF2: Grams | AG2: Pounds
A3: N/A | C3: 60 | D3: 12 | G3: 6 | AF3: =SUM(B3:AD3) -> 78 | AG3: =AF3/$AI$7 -> 0.17195767
A4: 45093 | B4: 79 | C4: 20 | AF4: =SUM(B4:AD4) -> 99 | AG4: =AF4/$AI$7 -> 0.21825397
A5: 45094 | B5: 31 | C5: 49 | AF5: =SUM(B5:AD5) -> 80 | AG5: =AF5/$AI$7 -> 0.17636684
A6: 45095 | B6: 73 | AF6: =SUM(B6:AD6) -> 73 | AG6: =AF6/$AI$7 -> 0.16093474
A7: 45097 | B7: 90 | AF7: =SUM(B7:AD7) -> 90 | AG7: =AF7/$AI$7 -> 0.1984127 | AI7: 453.6
A8: 45098 | B8: 64 | AF8: =SUM(B8:AD8) -> 64 | AG8: =AF8/$AI$7 -> 0.14109347
A9: 45101 | B9: 145 | C9: 7 | AF9: =SUM(B9:AD9) -> 152 | AG9: =AF9/$AI$7 -> 0.335097
A10: 45102 | B10: =139+43 -> 182 | H10: 41 | AF10: =SUM(B10:AD10) -> 223 | AG10: =AF10/$AI$7 -> 0.49162258
A11: 45103 | B11: 140 | AF11: =SUM(B11:AD11) -> 140 | AG11: =AF11/$AI$7 -> 0.30864198
A12: 45105 | B12: 110 | C12: 4 | AF12: =SUM(B12:AD12) -> 114 | AG12: =AF12/$AI$7 -> 0.25132275
A13: 45106 | B13: 93 | AF13: =SUM(B13:AD13) -> 93 | AG13: =AF13/$AI$7 -> 0.20502645
A14: 45108 | B14: 93 | AF14: =SUM(B14:AD14) -> 93 | AG14: =AF14/$AI$7 -> 0.20502645
A15: 45109 | B15: 86 | I15: 1 | AF15: =SUM(B15:AD15) -> 87 | AG15: =AF15/$AI$7 -> 0.19179894
A16: 45111 | B16: 62 | D16: 6 | I16: 1 | AF16: =SUM(B16:AD16) -> 69 | AG16: =AF16/$AI$7 -> 0.1521164
A17: 45113 | B17: 22 | C17: 25 | AF17: =SUM(B17:AD17) -> 47 | AG17: =AF17/$AI$7 -> 0.10361552
A18: 45114 | B18: 10 | AF18: =SUM(B18:AD18) -> 10 | AG18: =AF18/$AI$7 -> 0.022045855
A19: 45116 | B19: 5 | C19: 16 | H19: 13 | N19: 14 | AF19: =SUM(B19:AD19) -> 48 | AG19: =AF19/$AI$7 -> 0.10582011
A20: 45118 | N20: 33 | AF20: =SUM(B20:AD20) -> 33 | AG20: =AF20/$AI$7 -> 0.072751323
A21: 45121 | C21: 28 | D21: 18 | E21: 58 | AF21: =SUM(B21:AD21) -> 104 | AG21: =AF21/$AI$7 -> 0.2292769
A22: 45122 | B22: 22 | C22: 68 | E22: 88 | J22: 285 | N22: 32 | AF22: =SUM(B22:AD22) -> 495 | AG22: =AF22/$AI$7 -> 1.0912698
A23: 45123 | E23: 22 | AF23: =SUM(B23:AD23) -> 22 | AG23: =AF23/$AI$7 -> 0.048500882
A24: 45124 | E24: 108 | AF24: =SUM(B24:AD24) -> 108 | AG24: =AF24/$AI$7 -> 0.23809524
A25: 45126 | C25: 26 | E25: 330 | N25: 77 | P25: 380 | AF25: =SUM(B25:AD25) -> 813 | AG25: =AF25/$AI$7 -> 1.792328
A26: 45127 | C26: 22 | E26: 158 | AF26: =SUM(B26:AD26) -> 180 | AG26: =AF26/$AI$7 -> 0.3968254
A27: 45128 | L27: 33 | N27: 25 | AF27: =SUM(B27:AD27) -> 58 | AG27: =AF27/$AI$7 -> 0.12786596
A28: 45129 | E28: =164+98 -> 262 | M28: 26 | AF28: =SUM(B28:AD28) -> 288 | AG28: =AF28/$AI$7 -> 0.63492063
A29: 45130 | E29: 526 | N29: 21 | S29: 27 | AF29: =SUM(B29:AD29) -> 574 | AG29: =AF29/$AI$7 -> 1.2654321
A30: 45131 | C30: 25 | E30: 112 | N30: 58 | AF30: =SUM(B30:AD30) -> 195 | AG30: =AF30/$AI$7 -> 0.42989418
A31: 45132 | C31: 15 | E31: 194 | K31: 70 | AF31: =SUM(B31:AD31) -> 279 | AG31: =AF31/$AI$7 -> 0.61507937
A32: 45133 | L32: 172 | AF32: =SUM(B32:AD32) -> 172 | AG32: =AF32/$AI$7 -> 0.37918871
A33: 45134 | C33: 19 | E33: 214 | L33: 174 | N33: 65 | AF33: =SUM(B33:AD33) -> 472 | AG33: =AF33/$AI$7 -> 1.0405644
A34: 45135 | C34: 19 | E34: 382 | N34: 124 | P34: 174 | AF34: =SUM(B34:AD34) -> 699 | AG34: =AF34/$AI$7 -> 1.5410053
A35: 45136 | E35: 129 | I35: 1 | N35: 30 | O35: 25 | R35: 127 | AF35: =SUM(B35:AD35) -> 312 | AG35: =AF35/$AI$7 -> 0.68783069
A36: 45138 | C36: 41 | E36: =230+129 -> 359 | L36: =596+495-203-181+96+511 -> 1314 | M36: =318+128 -> 446 | N36: 87 | AF36: =SUM(B36:AD36) -> 2247 | AG36: =AF36/$AI$7 -> 4.9537037
A37: 45139 | E37: 15 | O37: 36 | R37: 98 | AF37: =SUM(B37:AD37) -> 149 | AG37: =AF37/$AI$7 -> 0.32848325
A38: 45140 | C38: 18 | E38: 166 | N38: 25 | O38: 34 | AF38: =SUM(B38:AD38) -> 243 | AG38: =AF38/$AI$7 -> 0.53571429
A39: 45143 | C39: 24 | E39: =751+476 -> 1227 | N39: 27 | O39: 85 | R39: =25+66 -> 91 | S39: =115+66 -> 181 | AF39: =SUM(B39:AD39) -> 1635 | AG39: =AF39/$AI$7 -> 3.6044974
A40: 45144 | C40: 52 | E40: 102 | J40: 327 | O40: 37 | S40: 30 | AF40: =SUM(B40:AD40) -> 548 | AG40: =AF40/$AI$7 -> 1.2081129
...

Sheet 2023 Totals
A1: Item | B1: SubType | C1: Total Weight (g) | D1: Total Weight (lbs)
A2: Green Beans | C2: =SUM('2023 Yield'!E:E) -> 14990.506 | D2: =C2/$I$4 -> 33.047852
A3: Tomato | B3: Red Cherry | C3: =SUM('2023 Yield'!N:N) -> 3896.2901 | D3: =C3/$I$4 -> 8.5897049
B4: Golden Cherry | C4: =SUM('2023 Yield'!O:O) -> 1519.6733 | D4: =C4/$I$4 -> 3.3502497 | H4: Grams to LBS | I4: 453.6
B5: San Marzano | C5: =SUM('2023 Yield'!S:S) -> 7266.0004 | D5: =C5/$I$4 -> 16.018519 | E5: =SUM(D3:D7) -> 55.31664 | H5: Grams to Kilograms | I5: 1000
B6: Golden Jubilee | C6: =SUM('2023 Yield'!R:R) -> 2254.4824 | D6: =C6/$I$4 -> 4.9701992
B7: Large | C7: =SUM('2023 Yield'!P:P) -> 10155.182 | D7: =C7/$I$4 -> 22.387967 | H7: Total (g) | I7: =SUM(C:C) -> 73615.056
A8: Raspberry | C8: =SUM('2023 Yield'!B:B) -> 2616.8814 | D8: =C8/$I$4 -> 5.7691389 | H8: Total (kg) | I8: =I7/I5 -> 73.615056
A9: Strawberry | C9: =SUM('2023 Yield'!C:C) -> 1601.7637 | D9: =C9/$I$4 -> 3.531225 | H9: Total (lbs) | I9: =SUM(D:D) -> 162.29069
A10: Snap Pea | C10: =SUM('2023 Yield'!D:D) -> 72.079365 | D10: =C10/$I$4 -> 0.15890513
A11: Onion | C11: =SUM('2023 Yield'!G:G) -> 12.013228 | D11: =C11/$I$4 -> 0.026484188
A12: Broccoli | C12: =SUM('2023 Yield'!H:H) -> 114.12566 | D12: =C12/$I$4 -> 0.25159978
A13: Blueberries | C13: =SUM('2023 Yield'!I:I) -> 6.0066138 | D13: =C13/$I$4 -> 0.013242094
A14: Cucumber | C14: =SUM('2023 Yield'!J:J) -> 1932.1274 | D14: =C14/$I$4 -> 4.2595402
A15: Green Pepper | C15: =SUM('2023 Yield'!K:K) -> 246.27116 | D15: =C15/$I$4 -> 0.54292585
A16: Plum | C16: =SUM('2023 Yield'!L:L) -> 3389.7324 | D16: =C16/$I$4 -> 7.4729549
A17: Black Berries | C17: =SUM('2023 Yield'!M:M) -> 945.04056 | D17: =C17/$I$4 -> 2.0834228
A18: Peaches | C18: =SUM('2023 Yield'!T:T) -> 3485.8382 | D18: =C18/$I$4 -> 7.6848284
A19: Corn | C19: =SUM('2023 Yield'!U:U) -> 3890.2835 | D19: =C19/$I$4 -> 8.5764628
A20: Banana Pepper | C20: =SUM('2023 Yield'!W:W) -> 90.099206 | D20: =C20/$I$4 -> 0.19863141
A21: Acorn Squash | C21: =SUM('2023 Yield'!X:X) -> 4915.4123 | D21: =C21/$I$4 -> 10.836447
A22: Potatoes | C22: =SUM('2023 Yield'!Y:Y) -> 1395.5366 | D22: =C22/$I$4 -> 3.0765798
A23: Butternut Squash | C23: =SUM('2023 Yield'!AA:AA) -> 8631.504 | D23: =C23/$I$4 -> 19.028889
A24: Jalapeno | C24: =SUM('2023 Yield'!AB:AB) -> 188.20723 | D24: =C24/$I$4 -> 0.41491894

Sheet 2024 Yield
A1: Date | B1: Strawberry | C1: Hulaberry | D1: Raspberry | E1: Blueberry | F1: Zucchini | G1: Green Beans | H1: 2023 Green Beans | I1: Blackberry | J1: Better Boy | K1: Beefsteak | L1: Purple | M1: Heirloom | N1: Bush Goliath | O1: Cherry Tomato | P1: Plum | Q1: Roma | R1: Potato | S1: Cucumber | T1: Spaghetti Squash | U1: Onion | V1: Peach | W1: Corn | X1: Jalapeno | Y1: Cannabis
A2: 45441 | B2: 417
A3: 45448 | B3: 456
A4: 45450 | B4: 283
A5: 45456 | B5: 270 | C5: 28 | D5: 28
A6: 45458 | B6: =35+42 -> 77
A7: 45461 | B7: 51 | C7: 18 | D7: 161
A8: 45463 | D8: 98
A9: 45464 | B9: 40 | D9: 81
A10: 45465 | B10: 40 | D10: 22
A11: 45468 | B11: 122 | D11: 110
A12: 45470 | B12: 44 | D12: 34
A13: 45472 | B13: 202 | C13: 6 | D13: 22
A14: 45474 | B14: 30 | D14: 62
A15: 45476 | B15: 62 | D15: 9
A16: 45478 | B16: 95
A17: 45486 | B17: 47 | E17: 4
A18: 45490 | E18: 12 | F18: 957 | G18: 14
A19: 45491 | E19: 29 | F19: 281 | I19: 29
A20: 45492 | B20: 46 | E20: 6
A21: 45493 | I21: 61
A22: 45494 | F22: 908 | J22: 228 | N22: 356 | O22: 5 | P22: 394
A23: 45495 | B23: 39 | F23: 1039
A24: 45496 | F24: 747
A25: 45497 | E25: 21 | I25: 33
A26: 45498 | J26: 132 | O26: 8
A27: 45499 | B27: 27 | E27: 3 | P27: =1680+1660+146 -> 3486 | R27: 550
A28: 45500 | J28: 339
A29: 45501 | B29: 40 | E29: 15
A30: 45502 | B30: 36 | G30: 70 | O30: 15 | P30: =1233+1736+1019+225 -> 4213 | S30: 948
A31: 45504 | E31: 23 | P31: 9500
A32: 45505 | B32: 74 | E32: 168 | F32: 376 | O32: 17 | P32: 2419 | S32: 404
A33: 45506 | P33: 2122
A34: 45507 | B34: 62 | E34: 10 | G34: 11 | O34: 17
A35: 45508 | F35: 319 | J35: 357 | O35: 6
A36: 45509 | I36: 279 | O36: 36
A37: 45511 | F37: 342 | O37: 37 | T37: 1318
A38: 45513 | B38: 145 | E38: 4 | F38: 420 | G38: 67 | I38: 312 | P38: 51 | S38: 1282 | U38: 133
A39: 45514 | B39: 36 | G39: 38 | J39: 73 | N39: 72 | O39: 53 | P39: =108+268 -> 376 | V39: =1274+473+772 -> 2519
A40: 45515 | F40: 1257
...

Sheet 2024 Totals
A1: Strawberry | B1: =SUM('2024 Yield'!B80:B999) -> 3899
A2: Hulaberry | B2: =SUM('2024 Yield'!C80:C999) -> 52
A3: Raspberry | B3: =SUM('2024 Yield'!D80:D999) -> 627
A4: Blueberry | B4: =SUM('2024 Yield'!E80:E999) -> 295
A5: Zucchini | B5: =SUM('2024 Yield'!F80:F999) -> 15381
A6: Green Beans | B6: =SUM('2024 Yield'!G80:G999) -> 1085 | E6: Total (g) | F6: =SUM(B:B) -> 91418
A7: 2023 Green Beans | B7: =SUM('2024 Yield'!H80:H999) -> 561 | E7: Total (lbs) | F7: =F6/453.6 -> 201.5388
A8: Blackberry | B8: =SUM('2024 Yield'!I80:I999) -> 774
A9: Better Boy | B9: =SUM('2024 Yield'!J80:J999) -> 2396
A10: Beefsteak | B10: =SUM('2024 Yield'!K80:K999) -> 3061
A11: Purple | B11: =SUM('2024 Yield'!L80:L999) -> 1011
A12: Heirloom | B12: =SUM('2024 Yield'!M2:M80) -> 10167
A13: Bush Goliath | B13: =SUM('2024 Yield'!N80:N999) -> 3019
A14: Cherry Tomato | B14: =SUM('2024 Yield'!O80:O999) -> 1810
A15: Plum | B15: =SUM('2024 Yield'!P80:P999) -> 22981
A16: Roma | B16: =SUM('2024 Yield'!Q80:Q999) -> 2079
A17: Potato | B17: =SUM('2024 Yield'!R80:R999) -> 550
A18: Cucumber | B18: =SUM('2024 Yield'!S80:S999) -> 10540
A19: Spaghetti Squash | B19: =SUM('2024 Yield'!T80:T999) -> 4913
A20: Onion | B20: =SUM('2024 Yield'!U80:U999) -> 133
A21: Peach | B21: =SUM('2024 Yield'!V80:V999) -> 5504
A22: Corn | B22: =SUM('2024 Yield'!W80:W999) -> 462
A23: Jalapeno | B23: =SUM('2024 Yield'!X80:X999) -> 74
A24: Cannabis | B24: =SUM('2024 Yield'!Y80:Y999) -> 44
A31: Date
A32: Strawberry
A33: Hulaberry
A34: Raspberry
A35: Blueberry
A36: Zucchini
A37: Green Beans
A38: 2023 Green Beans
A39: Blackberry
A40: Better Boy
A41: Beefsteak
A42: Purple
... A985: Cannabis

Sheet 2025 Yield
A1: Date | E1: Lettuce | J1: Peppers | Q1: Tomato
B2: Strawberry | C2: Zucchini | D2: Green Bean | E2: Romaine | F2: Little Gem | G2: Blueberry | H2: Plum | I2: Cucumber | J2: Jalapeno | K2: Anaheim | L2: Poblano | M2: Habanero | N2: Bell | O2: Corn | P2: Blackberry | Q2: Cherry | R2: San Marzano | S2: Heirloom | T2: Beefsteak | U2: Gold | V2: Peach | W2: Cantaloupe
B3: =SUM(B4:B1002) -> 3296 | C3: =SUM(C4:C1002) -> 24614 | D3: =SUM(D4:D1002) -> 1294 | E3: =SUM(E4:E1002) -> 620 | F3: =SUM(F4:F1002) -> 125 | G3: =SUM(G4:G1002) -> 541 | H3: =SUM(H4:H1002) -> 46436.48 | I3: =SUM(I4:I1002) -> 5273 | ... W3: =SUM(W4:W1002) -> 3778
A4: 45805 | B4: =976 + 70 -> 1046 | Z4: Total (g) | AA4: =SUM(A3:W3) -> 134928.48
A5: 45806 | B5: 263 | Z5: Grams to LBS | AA5: 453.6
A6: 45807 | B6: 100 | Z6: Grams to Kilograms | AA6: 1000
A7: 45809 | B7: 84
A8: 45814 | B8: 371
A9: 45818 | B9: 97 | E9: 66 | Z9: Total (kg) | AA9: =AA4/AA6 -> 134.92848
A10: 45822 | B10: 164 | E10: 110 | Z10: Total (lbs) | AA10: =SUM(AA4/AA5) -> 297.46138
A11: 45826 | B11: 65
A12: 45828 | C12: 403
A13: 45833 | B13: 53 | D13: 14
A14: 45835 | F14: 125
A15: 45837 | E15: 248
A16: 45840 | C16: 536 | D16: 97 | E16: =115+81 -> 196
A17: 45841 | B17: 10 | D17: 33
A18: 45842 | B18: 23 | C18: 344 | D18: 21 | G18: 1
A19: 45845 | C19: 1309 | G19: 1 | H19: 348
A20: 45846 | C20: 681 | G20: 4
A21: 45847 | B21: 10 | D21: =128+58+93 -> 279 | H21: =366+345+124 -> 835 | J21: 16
A22: 45848 | G22: 3
A23: 45851 | C23: 1528 | G23: 24 | H23: =1840+915+2300+217+1804 -> 7076
A24: 45852 | C24: 2201 | G24: 31 | H24: =1941+421+164 -> 2526 | I24: 302 | J24: 23 | L24: 31
A25: 45853 | C25: 265 | D25: 229 | G25: 25 | H25: 2270 | O25: 219
A26: 45854 | P26: 50
A27: 45855 | C27: 1019 | I27: 205
A28: 45856 | C28: 579 | I28: 524
A29: 45857 | B29: 17 | C29: 416 | D29: 97 | G29: 47 | H29: 7257.48 | L29: 47 | P29: 147
A30: 45858 | B30: 6 | C30: 451 | H30: =51+4082+416+1000+116 -> 5665 | I30: 255 | Q30: 2
A31: 45859 | C31: 457 | G31: 48
A32: 45860 | G32: 20
A33: 45861 | C33: 660 | G33: 54 | I33: 691
A34: 45862 | B34: 18 | C34: 1152 | G34: 35 | H34: =1922+1311+865+6486 -> 10584 | Q34: 1
A35: 45863 | B35: 26 | D35: 152 | J35: 29 | L35: 52 | Q35: 11
A36: 45864 | B36: 43 | C36: =1000+319+343 -> 1662 | G36: 31 | H36: 3538 | I36: 189 | O36: 463
A37: 45865 | C37: 883 | H37: =3583+313 -> 3896 | Q37: 24
A38: 45866 | C38: 250 | H38: 1279 | I38: 322
A39: 45867 | B39: 7 | G39: 72 | Q39: 16
A40: 45868 | B40: 120 | C40: 566 | D40: 76 | H40: 1162 | I40: 198
...

Sheet 2025 Totals
B1: Total (g) | C1: Total (kg) | D1: Total (lbs) | E1: Gram to LBS Multiplier
A2: Strawberry | B2: =SUM('2025 Yield'!B4:B1000) -> 3296 | C2: =B2/1000 -> 3.296 | D2: =B2/E2 -> 7.2663139 | E2: 453.6
A3: Zucchini | B3: =SUM('2025 Yield'!C4:C1000) -> 24614 | C3: =B3/1000 -> 24.614 | D3: =B3/E2 -> 54.263668
A4: Green Bean | B4: =SUM('2025 Yield'!D4:D1000) -> 1294 | C4: =B4/1000 -> 1.294 | D4: =B4/E2 -> 2.8527337
A5: Romaine | B5: =SUM('2025 Yield'!E6:E1000) -> 620 | C5: =B5/1000 -> 0.62 | D5: =B5 / E$2 -> 1.366843
A6: Little Gem | B6: =SUM('2025 Yield'!F4:F1000) -> 125 | C6: =B6/1000 -> 0.125 | D6: =B6 / E$2 -> 0.27557319
A7: Blueberry | B7: =SUM('2025 Yield'!G4:G1000) -> 541 | C7: =B7/1000 -> 0.541 | D7: =B7 / E$2 -> 1.1926808
A8: Plum | B8: =SUM('2025 Yield'!H4:H1000) -> 46436.48 | C8: =B8/1000 -> 46.43648 | D8: =B8 / E$2 -> 102.37319
A9: Cucumber | B9: =SUM('2025 Yield'!I4:I1000) -> 5273 | C9: =B9/1000 -> 5.273 | D9: =B9 / E$2 -> 11.62478
A10: Jalapeno | B10: =SUM('2025 Yield'!J4:J1000) -> 1426 | C10: =B10/1000 -> 1.426 | D10: =B10 / E$2 -> 3.143739
A11: Anaheim | B11: =SUM('2025 Yield'!K4:K1000) -> 866 | C11: =B11/1000 -> 0.866 | D11: =B11 / E$2 -> 1.9091711
A12: Poblano | B12: =SUM('2025 Yield'!L4:L1000) -> 1472 | C12: =B12/1000 -> 1.472 | D12: =B12 / E$2 -> 3.2451499
A13: Habanero | B13: =SUM('2025 Yield'!M4:M1000) -> 205 | C13: =B13/1000 -> 0.205 | D13: =B13 / E$2 -> 0.45194004
A14: Bell | B14: =SUM('2025 Yield'!N4:N1000) -> 503 | C14: =B14/1000 -> 0.503 | D14: =B14 / E$2 -> 1.1089065
A15: Corn | B15: =SUM('2025 Yield'!O4:O1000) -> 1985 | C15: =B15/1000 -> 1.985 | D15: =B15 / E$2 -> 4.3761023
A16: Blackberry | B16: =SUM('2025 Yield'!P4:P1000) -> 197 | C16: =B16/1000 -> 0.197 | D16: =B16 / E$2 -> 0.43430335
A17: Cherry | B17: =SUM('2025 Yield'!Q4:Q1000) -> 4094 | C17: =B17/1000 -> 4.094 | D17: =B17 / E$2 -> 9.0255732
A18: San Marzano | B18: =SUM('2025 Yield'!R4:R1000) -> 19809 | C18: =B18/1000 -> 19.809 | D18: =B18 / E$2 -> 43.670635
A19: Heirloom | B19: =SUM('2025 Yield'!S4:S1000) -> 1308 | C19: =B19/1000 -> 1.308 | D19: =B19 / E$2 -> 2.8835979
A20: Beefsteak | B20: =SUM('2025 Yield'!T4:T1000) -> 7970 | C20: =B20/1000 -> 7.97 | D20: =B20 / E$2 -> 17.570547
A21: Gold | B21: =SUM('2025 Yield'!U4:U1000) -> 2725 | C21: =B21/1000 -> 2.725 | D21: =B21 / E$2 -> 6.0074956
A22: Peach | B22: =SUM('2025 Yield'!V4:V1000) -> 6391 | C22: =B22/1000 -> 6.391 | D22: =B22 / E$2 -> 14.089506
A23: Cantaloupe | B23: =SUM('2025 Yield'!W4:W1000) -> 3778 | C23: =B23/1000 -> 3.778 | D23: =B23 / E$2 -> 8.3289242
A25: Totals | B25: =SUM(B2:B23) -> 134928.48 | C25: =SUM(C2:C24) -> 134.92848 | D25: =SUM(D2:D24) -> 297.46138
